<?xml version="1.0"?>
<robot name="dtw_robot" xmlns:xacro="http://ros.org/wiki/xacro">
  <material name="gray">
    <color rgba="0.5 0.5 0.5 1.0" />
  </material>
  <material name="red">
    <color rgba="1.0 0.0 0.0 1.0" />
  </material>
  <material name="green">
    <color rgba="0.0 1.0 0.0 1.0" />
  </material>
  <material name="blue">
    <color rgba="0.0 0.0 1.0 1.0" />
  </material>
  <material name="black">
    <color rgba="0.0 0.0 0.0 1.0" />
  </material>

  <!-- Rear wheel macro -->
  <xacro:macro name="rear_wheel_macro" params="parent prefix xyz">
    <joint name="${prefix}_joint" type="continuous">
      <origin xyz="${xyz}" rpy="${radians(-90)} 0 0" />
      <parent link="${parent}" />
      <child link="${prefix}_link" />
      <axis xyz="0 0 1" />
    </joint>
    <transmission name="${prefix}_trans" type="SimpleTransmission">
      <type>transmission_interface/SimpleTransmission</type>
      <actuator name="${prefix}_motor">
        <mechanicalReduction>1</mechanicalReduction>
      </actuator>
      <joint name="${prefix}_joint">
        <hardwareInterface>hardware_interface/VelocityJointInterface</hardwareInterface>
      </joint>
    </transmission>
    <link name="${prefix}_link">
      <inertial>
        <origin xyz="0 0 0" rpy="0 0 0" />
        <mass value="0.1" />
        <inertia ixx="0.0001" ixy="0.0" ixz="0.0" iyy="0.0001" iyz="0.0" izz="0.0001" />
      </inertial>
      <visual>
        <geometry>
          <cylinder radius="0.1325" length="0.05" />
        </geometry>
        <material name="red" />
      </visual>
      <collision>
        <geometry>
          <cylinder radius="0.1325" length="0.05" />
        </geometry>
      </collision>
    </link>
    <gazebo reference="${prefix}_link">
      <material>Gazebo/Red</material>
      <mu1 value="3.5" />
      <mu2 value="3.5" />
      <kp value="10000" />
      <kd value="10" />
    </gazebo>
  </xacro:macro>

  <!-- Front wheel macro -->
  <xacro:macro name="front_wheel_macro" params="parent prefix xyz">
    <link name="front_${prefix}_link">
      <collision>
        <geometry>
          <sphere radius="0.1325" />
        </geometry>
      </collision>
      <visual>
        <geometry>
          <cylinder length="0.05" radius="0.1325" />
        </geometry>
        <material name="black" />
      </visual>
      <inertial>
        <origin xyz="0 0 0" rpy="0 0 0" />
        <mass value="1.0" />
        <inertia ixx="1.0" ixy="0.0" ixz="0.0"
          iyy="1.0" iyz="0.0"
          izz="1.0" />
      </inertial>
    </link>
    <joint name="front_${prefix}_joint" type="fixed">
      <parent link="${parent}" />
      <child link="front_${prefix}_link" />
      <origin xyz="${xyz}" rpy="${radians(90)} 0 0" />
      <axis xyz="0 0 1" />
    </joint>
    <gazebo reference="front_${prefix}_link">
      <material>Gazebo/Black</material>
      <mu1 value="0.01" />
      <mu2 value="0.01" />
    </gazebo>
  </xacro:macro>

  <link name="base_link" />

  <joint name="base_body_joint" type="fixed">
    <parent link="base_link" />
    <child link="base_floor" />
    <origin xyz="0.3 0 0.0" rpy="0 0 0" />
  </joint>

  <link name="base_floor">
    <inertial>
      <origin xyz="0 0 0" rpy="0 0 0" />
      <mass value="1.0" />
      <inertia ixx="0.001" ixy="0.0" ixz="0.0" iyy="0.001" iyz="0.0" izz="0.001" />
    </inertial>
    <visual>
      <origin xyz="0 0 0" rpy="0 0 0" />
      <geometry>
        <box size="0.600 0.400 0.050" />
      </geometry>
      <material name="green" />
    </visual>
    <collision>
      <origin xyz="0 0 0" rpy="0 0 0" />
      <geometry>
        <box size="0.600 0.400 0.050" />
      </geometry>
    </collision>
  </link>
  <gazebo reference="base_floor">
    <material>Gazebo/Green</material>
  </gazebo>

  <xacro:rear_wheel_macro prefix="left_wheel" parent="base_floor" xyz="-0.3 0.245 0" />
  <xacro:rear_wheel_macro prefix="right_wheel" parent="base_floor" xyz="-0.3 -0.245 0" />
  <xacro:front_wheel_macro prefix="left_wheel" parent="base_floor" xyz="0.3 -0.245 0" />
  <xacro:front_wheel_macro prefix="right_wheel" parent="base_floor" xyz="0.3 0.245 0" />

  <joint name="lidar_joint" type="fixed">
    <parent link="base_link" />
    <child link="multiscan_link" />
    <origin xyz="0 0 1.60" rpy="0 0 0" />
  </joint>
  <link name="multiscan_link">
    <visual>
      <geometry>
        <cylinder radius="0.030" length="0.086" />
      </geometry>
      <origin xyz="0 0 0" rpy="0 0 0" />
      <material name="blue" />
    </visual>
    <collision>
      <geometry>
        <cylinder radius="0.0" length="0.086" />
      </geometry>
      <origin xyz="0 0 0" rpy="0 0 0" />
    </collision>
    <inertial>
      <origin xyz="0 0 0" rpy="0 0 0" />
      <mass value="0.25" />
      <inertia ixx="0.00021033333"
        ixy="0" ixz="0"
        iyx="0" iyy="0.00021033333"
        iyz="0"
        izx="0" izy="0" izz="0.0001125" />
    </inertial>
  </link>

  <joint name="gps_joint" type="fixed">
    <parent link="base_link" />
    <child link="gps" />
    <origin xyz="0.3 0 0.70" rpy="0 0 0" />
  </joint>
  <link name="gps">
    <inertial>
      <origin xyz="0 0 0" rpy="0 0 0" />
      <mass value="0.10"/>
      <inertia ixx="0.001" ixy="0.0" ixz="0.0" iyy="0.001" iyz="0.0" izz="0.001" />
    </inertial>
    <visual>
      <origin xyz="0 0 0" rpy="0 0 0" />
      <geometry>
        <box size="0.10 0.10 0.030" />
      </geometry>
      <material name="green" />
    </visual>
    <collision>
      <origin xyz="0 0 0" rpy="0 0 0" />
      <geometry>
        <box size="0.10 0.10 0.030" />
      </geometry>
    </collision>
  </link>

  <joint name="imu_joint" type="fixed">
    <parent link="base_link" />
    <child link="imu_link" />
    <origin xyz="0.0 0 1.00" rpy="0 0 0" />
  </joint>
  <link name="imu_link">
    <inertial>
      <origin xyz="0 0 0" rpy="0 0 0" />
      <mass value="0.10"/>
      <inertia ixx="0.001" ixy="0.0" ixz="0.0" iyy="0.001" iyz="0.0" izz="0.001" />
    </inertial>
    <visual>
      <origin xyz="0 0 0" rpy="0 0 0" />
      <geometry>
        <box size="0.050 0.050 0.030" />
      </geometry>
      <material name="green" />
    </visual>
    <collision>
      <origin xyz="0 0 0" rpy="0 0 0" />
      <geometry>
        <box size="0.050 0.050 0.030" />
      </geometry>
    </collision>
  </link>

  <gazebo reference="lidar_link">
    <material>Gazebo/Blue</material>
    <sensor type="ray" name="lidar">
      <pose>0 0 0 0 0 0</pose>
      <visualize>true</visualize>
      <update_rate>15</update_rate>
      <ray>
        <scan>
          <horizontal>
            <samples>400</samples>
            <resolution>1</resolution>
            <min_angle>-2.35619449</min_angle>
            <max_angle>2.35619449</max_angle>
          </horizontal>
        </scan>
        <range>
          <min>0.05</min>
          <max>25.0</max>
          <resolution>0.001</resolution>
        </range>
        <noise>
          <type>gaussian</type>
          <mean>0.0</mean>
          <stddev>0.01</stddev>
        </noise>
      </ray>
      <plugin name="gazebo_ros_lidar_controller" filename="libgazebo_ros_laser.so">
        <topicName>scan</topicName>
        <frameName>lidar_link</frameName>
      </plugin>
    </sensor>
  </gazebo>

  <gazebo>
    <plugin name="gazebo_ros_control" filename="libgazebo_ros_control.so">
      <robotNamespace>/whill_simulator</robotNamespace>
      <robotSimType>gazebo_ros_control/DefaultRobotHWSim</robotSimType>
      <legacyModeNS>true</legacyModeNS>
    </plugin>
  </gazebo>
  <gazebo>
    <plugin name="ground_truth" filename="libgazebo_ros_p3d.so">
      <frameName>world</frameName>
      <bodyName>base_link</bodyName>
      <topicName>/tracker</topicName>
      <updateRate>10.0</updateRate>
    </plugin>
  </gazebo>
</robot>